<sdf version='1.7'>
  <world name='default'>
    <light name='sun' type='directional'>
      <cast_shadows>1</cast_shadows>
      <pose>0 0 10 0 -0 0</pose>
      <diffuse>0.8 0.8 0.8 1</diffuse>
      <specular>0.2 0.2 0.2 1</specular>
      <attenuation>
        <range>1000</range>
        <constant>0.9</constant>
        <linear>0.01</linear>
        <quadratic>0.001</quadratic>
      </attenuation>
      <direction>-0.5 0.1 -0.9</direction>
      <spot>
        <inner_angle>0</inner_angle>
        <outer_angle>0</outer_angle>
        <falloff>0</falloff>
      </spot>
    </light>
    <model name='ground_plane'>
      <static>1</static>
      <link name='link'>
        <collision name='collision'>
          <geometry>
            <plane>
              <normal>0 0 1</normal>
              <size>100 100</size>
            </plane>
          </geometry>
          <surface>
            <friction>
              <ode>
                <mu>100</mu>
                <mu2>50</mu2>
              </ode>
              <torsional>
                <ode/>
              </torsional>
            </friction>
            <contact>
              <ode/>
            </contact>
            <bounce/>
          </surface>
          <max_contacts>10</max_contacts>
        </collision>
        <visual name='visual'>
          <cast_shadows>0</cast_shadows>
          <geometry>
            <plane>
              <normal>0 0 1</normal>
              <size>100 100</size>
            </plane>
          </geometry>
          <material>
            <script>
              <uri>file://media/materials/scripts/gazebo.material</uri>
              <name>Gazebo/Grey</name>
            </script>
          </material>
        </visual>
        <self_collide>0</self_collide>
        <enable_wind>0</enable_wind>
        <kinematic>0</kinematic>
      </link>
    </model>
    <gravity>0 0 -38.8</gravity>
    <magnetic_field>6e-06 2.3e-05 -4.2e-05</magnetic_field>
    <atmosphere type='adiabatic'/>
    <physics type='ode'>
      <max_step_size>0.001</max_step_size>
      <real_time_factor>1</real_time_factor>
      <real_time_update_rate>1000</real_time_update_rate>
    </physics>
    <scene>
      <ambient>0.4 0.4 0.4 1</ambient>
      <background>0.7 0.7 0.7 1</background>
      <shadows>1</shadows>
    </scene>
    <wind/>
    <spherical_coordinates>
      <surface_model>EARTH_WGS84</surface_model>
      <latitude_deg>0</latitude_deg>
      <longitude_deg>0</longitude_deg>
      <elevation>0</elevation>
      <heading_deg>0</heading_deg>
    </spherical_coordinates>
    <model name='mehmat_parkovka'>
      <static>1</static>
      <link name='link'>
        <collision name='collision'>
          <geometry>
            <mesh>
              <scale>1 1 1</scale>
              <uri>model://mehmat_parkovka/meshes/Parkovka.obj</uri>
            </mesh>
          </geometry>
          <max_contacts>10</max_contacts>
          <surface>
            <contact>
              <ode/>
            </contact>
            <bounce/>
            <friction>
              <torsional>
                <ode/>
              </torsional>
              <ode/>
            </friction>
          </surface>
        </collision>
        <visual name='visual'>
          <geometry>
            <mesh>
              <scale>1 1 1</scale>
              <uri>model://mehmat_parkovka/meshes/Parkovka.obj</uri>
            </mesh>
          </geometry>
        </visual>
        <self_collide>0</self_collide>
        <enable_wind>0</enable_wind>
        <kinematic>0</kinematic>
      </link>
      <pose>0.250322 -0.301596 0 0 -0 0</pose>
    </model>
    <state world_name='default'>
      <sim_time>693 303000000</sim_time>
      <real_time>1528 440871059</real_time>
      <wall_time>1716311817 973684327</wall_time>
      <iterations>436486</iterations>
      <model name='ground_plane'>
        <pose>0 0 0 0 -0 0</pose>
        <scale>1 1 1</scale>
        <link name='link'>
          <pose>0 0 0 0 -0 0</pose>
          <velocity>0 0 0 0 -0 0</velocity>
          <acceleration>0 0 0 0 -0 0</acceleration>
          <wrench>0 0 0 0 -0 0</wrench>
        </link>
      </model>
      <model name='mehmat_parkovka'>
        <pose>-12.0234 12.1338 5.14799 1.57 -0 0</pose>
        <scale>1 1 1</scale>
        <link name='link'>
          <pose>-12.0234 12.1338 5.14799 1.57 -0 0</pose>
          <velocity>0 0 0 0 -0 0</velocity>
          <acceleration>0 0 0 0 -0 0</acceleration>
          <wrench>0 0 0 0 -0 0</wrench>
        </link>
      </model>
      <model name='potrol'>
        <pose>20.6988 -14.055 1.17137 0.000691 -0.013489 3.09776</pose>
        <scale>1 1 1</scale>
        <link name='base_link'>
          <pose>20.6988 -14.055 1.17137 0.000691 -0.013489 3.09776</pose>
          <velocity>-2.69587 0.112812 0.01966 0.052598 -0.014328 0.025119</velocity>
          <acceleration>-9.48023 -10.8422 72.1778 -2.15197 -1.32248 -2.11035</acceleration>
          <wrench>-284.407 -325.266 2165.33 0 -0 0</wrench>
        </link>
        <link name='wheel_backward_left_link'>
          <pose>20.8544 -14.2826 1.19908 -1.56763 1.08315 3.10059</pose>
          <velocity>-2.69013 0.114066 0.009788 1.62087 1.30955 -3.06041</velocity>
          <acceleration>6.96964 -3.1073 55.358 -1.41668 1.47368 0.992822</acceleration>
          <wrench>28.5755 -12.7399 226.968 0 -0 0</wrench>
        </link>
        <link name='wheel_backward_right_link'>
          <pose>20.8737 -13.842 1.19877 -1.56914 0.456127 3.09851</pose>
          <velocity>-2.70219 0.116099 0.033541 1.62202 1.28237 -3.05978</velocity>
          <acceleration>-20.7728 -0.399483 62.1481 2.87728 -1.17802 2.1631</acceleration>
          <wrench>-85.1687 -1.63788 254.807 0 -0 0</wrench>
        </link>
        <link name='wheel_connnect_frame_forward_left_link'>
          <pose>20.3848 -14.2116 1.20814 -0.000792 0.013483 -0.051446</pose>
          <velocity>-2.69092 0.103072 0.005106 -0.028066 -0.015372 0.296595</velocity>
          <acceleration>3.01536 -30.1936 93.7328 -0.857788 -1.18092 -0.114345</acceleration>
          <wrench>3.01536 -30.1936 93.7328 0 -0 0</wrench>
        </link>
        <link name='wheel_connnect_frame_forward_right_link'>
          <pose>20.3997 -13.8716 1.2079 0.000606 -0.013494 3.10385</pose>
          <velocity>-2.69919 0.102989 0.023145 0.135073 -0.012665 -0.164773</velocity>
          <acceleration>-15.7809 -30.0113 97.7055 -1.30623 -0.715234 -2.46802</acceleration>
          <wrench>-15.7809 -30.0113 97.7055 0 -0 0</wrench>
        </link>
        <link name='wheel_forward_left_link'>
          <pose>20.3822 -14.2615 1.20818 0.00137 1.36635 3.0899</pose>
          <velocity>-2.9894 0.11731 0.006898 1.32053 1.27361 -2.83352</velocity>
          <acceleration>3.56476 -29.556 93.4394 -1.84187 1.26089 -0.264175</acceleration>
          <wrench>14.6155 -121.179 383.102 0 -0 0</wrench>
        </link>
        <link name='wheel_forward_right_link'>
          <pose>20.4016 -13.8216 1.20789 0.00386 1.2679 3.10755</pose>
          <velocity>-3.01797 0.116613 0.038494 1.81542 1.24533 3.02254</velocity>
          <acceleration>-29.7632 -29.7671 106.984 -0.44788 -1.47263 -0.350283</acceleration>
          <wrench>-122.029 -122.045 438.635 0 -0 0</wrench>
        </link>
      </model>
      <light name='sun'>
        <pose>0 0 10 0 -0 0</pose>
      </light>
      <light name='user_point_light_0'>
        <pose>14.8399 1.05542 7 0 -0 0</pose>
      </light>
    </state>
    <light name='user_point_light_0' type='point'>
      <pose>14.8399 1.05542 1 0 -0 0</pose>
      <diffuse>0.5 0.5 0.5 1</diffuse>
      <specular>0.1 0.1 0.1 1</specular>
      <attenuation>
        <range>20</range>
        <constant>0.5</constant>
        <linear>0.01</linear>
        <quadratic>0.001</quadratic>
      </attenuation>
      <cast_shadows>0</cast_shadows>
      <direction>0 0 -1</direction>
      <spot>
        <inner_angle>0</inner_angle>
        <outer_angle>0</outer_angle>
        <falloff>0</falloff>
      </spot>
    </light>
    <gui fullscreen='0'>
      <camera name='user_camera'>
        <pose>14.5444 -16.4729 5.38221 0 -0.161788 -2.97039</pose>
        <view_controller>orbit</view_controller>
        <projection_type>perspective</projection_type>
      </camera>
    </gui>
    <model name='potrol'>
      <link name='base_link'>
        <inertial>
          <pose>0 0 0 0 -0 0</pose>
          <mass>30</mass>
          <inertia>
            <ixx>1.4408</ixx>
            <ixy>0</ixy>
            <ixz>0</ixz>
            <iyy>2.13398</iyy>
            <iyz>0</iyz>
            <izz>1.19318</izz>
          </inertia>
        </inertial>
        <collision name='base_link_collision'>
          <pose>0 0 0 0 -0 0</pose>
          <geometry>
            <mesh>
              <scale>1 1 1</scale>
              <uri>model://potrol_description_cmake/meshes/potrol_frame_v2.dae</uri>
            </mesh>
          </geometry>
          <max_contacts>10</max_contacts>
          <surface>
            <contact>
              <ode/>
            </contact>
            <bounce/>
            <friction>
              <torsional>
                <ode/>
              </torsional>
              <ode/>
            </friction>
          </surface>
        </collision>
        <visual name='base_link_visual'>
          <pose>0 0 0 0 -0 0</pose>
          <geometry>
            <mesh>
              <scale>1 1 1</scale>
              <uri>model://potrol_description_cmake/meshes/potrol_frame_v2.dae</uri>
            </mesh>
          </geometry>
        </visual>
        <visual name='base_link_fixed_joint_lump__camera_link_visual_1'>
          <pose>0.37 -0.004 0.035 0 -0 0</pose>
          <geometry>
            <box>
              <size>0.01 0.03 0.03</size>
            </box>
          </geometry>
          <material>
            <script>
              <name>Gazebo/Red</name>
              <uri>file://media/materials/scripts/gazebo.material</uri>
            </script>
          </material>
        </visual>
        <sensor name='camera' type='depth'>
          <visualize>1</visualize>
          <update_rate>10</update_rate>
          <camera>
            <horizontal_fov>1.089</horizontal_fov>
            <image>
              <format>B8G8R8</format>
              <width>640</width>
              <height>480</height>
            </image>
            <clip>
              <near>0.05</near>
              <far>8</far>
            </clip>
          </camera>
          <plugin name='camera_controller' filename='libgazebo_ros_camera.so'>
            <frame_name>camera_link_optical</frame_name>
            <min_depth>0.1</min_depth>
            <max_depth>100.0</max_depth>
          </plugin>
          <pose>0.37 -0.004 0.035 0 -0 0</pose>
        </sensor>
        <self_collide>0</self_collide>
        <enable_wind>0</enable_wind>
        <kinematic>0</kinematic>
      </link>
      <joint name='wheel_backward_left_joint' type='revolute'>
        <pose relative_to='base_link'>-0.16505 0.220515 0.029786 -1.57 0 0</pose>
        <parent>base_link</parent>
        <child>wheel_backward_left_link</child>
        <axis>
          <xyz>0 0 1</xyz>
          <limit>
            <lower>-1e+16</lower>
            <upper>1e+16</upper>
          </limit>
          <dynamics>
            <spring_reference>0</spring_reference>
            <spring_stiffness>0</spring_stiffness>
          </dynamics>
        </axis>
      </joint>
      <link name='wheel_backward_left_link'>
        <pose relative_to='wheel_backward_left_joint'>0 0 0 0 -0 0</pose>
        <inertial>
          <pose>0 0 0 0 -0 0</pose>
          <mass>4.1</mass>
          <inertia>
            <ixx>1.24701</ixx>
            <ixy>0</ixy>
            <ixz>0</ixz>
            <iyy>1.90173</iyy>
            <iyz>0</iyz>
            <izz>1.24574</izz>
          </inertia>
        </inertial>
        <collision name='wheel_backward_left_link_collision'>
          <pose>0 0 0 0 -0 0</pose>
          <geometry>
            <cylinder>
              <length>0.04</length>
              <radius>0.075</radius>
            </cylinder>
          </geometry>
          <surface>
            <contact>
              <ode/>
            </contact>
            <friction>
              <ode>
                <mu2>1</mu2>
              </ode>
              <torsional>
                <ode/>
              </torsional>
            </friction>
            <bounce/>
          </surface>
          <max_contacts>10</max_contacts>
        </collision>
        <visual name='wheel_backward_left_link_visual'>
          <pose>0 0 0 0 -0 0</pose>
          <geometry>
            <cylinder>
              <length>0.04</length>
              <radius>0.075</radius>
            </cylinder>
          </geometry>
          <material>
            <script>
              <name>Gazebo/Gray</name>
              <uri>file://media/materials/scripts/gazebo.material</uri>
            </script>
          </material>
        </visual>
        <self_collide>0</self_collide>
        <enable_wind>0</enable_wind>
        <kinematic>0</kinematic>
        <mu>1.0</mu>
      </link>
      <joint name='wheel_backward_right_joint' type='revolute'>
        <pose relative_to='base_link'>-0.16505 -0.220515 0.029786 -1.57 0 0</pose>
        <parent>base_link</parent>
        <child>wheel_backward_right_link</child>
        <axis>
          <xyz>0 0 1</xyz>
          <limit>
            <lower>-1e+16</lower>
            <upper>1e+16</upper>
          </limit>
          <dynamics>
            <spring_reference>0</spring_reference>
            <spring_stiffness>0</spring_stiffness>
          </dynamics>
        </axis>
      </joint>
      <link name='wheel_backward_right_link'>
        <pose relative_to='wheel_backward_right_joint'>0 0 0 0 -0 0</pose>
        <inertial>
          <pose>0 0 0 0 -0 0</pose>
          <mass>4.1</mass>
          <inertia>
            <ixx>1.24701</ixx>
            <ixy>0</ixy>
            <ixz>0</ixz>
            <iyy>1.90173</iyy>
            <iyz>0</iyz>
            <izz>1.24574</izz>
          </inertia>
        </inertial>
        <collision name='wheel_backward_right_link_collision'>
          <pose>0 0 0 0 -0 0</pose>
          <geometry>
            <cylinder>
              <length>0.04</length>
              <radius>0.075</radius>
            </cylinder>
          </geometry>
          <surface>
            <contact>
              <ode/>
            </contact>
            <friction>
              <ode>
                <mu2>1</mu2>
              </ode>
              <torsional>
                <ode/>
              </torsional>
            </friction>
            <bounce/>
          </surface>
          <max_contacts>10</max_contacts>
        </collision>
        <visual name='wheel_backward_right_link_visual'>
          <pose>0 0 0 0 -0 0</pose>
          <geometry>
            <cylinder>
              <length>0.04</length>
              <radius>0.075</radius>
            </cylinder>
          </geometry>
          <material>
            <script>
              <name>Gazebo/Gray</name>
              <uri>file://media/materials/scripts/gazebo.material</uri>
            </script>
          </material>
        </visual>
        <self_collide>0</self_collide>
        <enable_wind>0</enable_wind>
        <kinematic>0</kinematic>
        <mu>1.0</mu>
      </link>
      <joint name='wheel_connnect_frame_forward_left_joint' type='revolute'>
        <pose relative_to='base_link'>0.307287 0.170165 0.032513 0 -0 3.14</pose>
        <parent>base_link</parent>
        <child>wheel_connnect_frame_forward_left_link</child>
        <axis>
          <xyz>0 0 1</xyz>
          <limit>
            <lower>-1e+16</lower>
            <upper>1e+16</upper>
          </limit>
          <dynamics>
            <spring_reference>0</spring_reference>
            <spring_stiffness>0</spring_stiffness>
          </dynamics>
        </axis>
      </joint>
      <link name='wheel_connnect_frame_forward_left_link'>
        <pose relative_to='wheel_connnect_frame_forward_left_joint'>0 0 0 0 -0 0</pose>
        <inertial>
          <pose>0 0 0 0 -0 0</pose>
          <mass>1</mass>
          <inertia>
            <ixx>0.631229</ixx>
            <ixy>0</ixy>
            <ixz>0</ixz>
            <iyy>0.631229</iyy>
            <iyz>0</iyz>
            <izz>1.15312</izz>
          </inertia>
        </inertial>
        <collision name='wheel_connnect_frame_forward_left_link_collision'>
          <pose>0 0 0 0 -0 0</pose>
          <geometry>
            <mesh>
              <scale>1 1 1</scale>
              <uri>model://potrol_description_cmake/meshes/connnect_frame.dae</uri>
            </mesh>
          </geometry>
          <max_contacts>10</max_contacts>
          <surface>
            <contact>
              <ode/>
            </contact>
            <bounce/>
            <friction>
              <torsional>
                <ode/>
              </torsional>
              <ode/>
            </friction>
          </surface>
        </collision>
        <visual name='wheel_connnect_frame_forward_left_link_visual'>
          <pose>0 0 0 0 -0 0</pose>
          <geometry>
            <mesh>
              <scale>1 1 1</scale>
              <uri>model://potrol_description_cmake/meshes/connnect_frame.dae</uri>
            </mesh>
          </geometry>
        </visual>
        <self_collide>0</self_collide>
        <enable_wind>0</enable_wind>
        <kinematic>0</kinematic>
      </link>
      <joint name='wheel_forward_left_joint' type='revolute'>
        <pose relative_to='wheel_connnect_frame_forward_left_link'>0 -0.05 0 0 -0 3.14</pose>
        <parent>wheel_connnect_frame_forward_left_link</parent>
        <child>wheel_forward_left_link</child>
        <axis>
          <xyz>0 1 0</xyz>
          <limit>
            <lower>-1e+16</lower>
            <upper>1e+16</upper>
          </limit>
          <dynamics>
            <spring_reference>0</spring_reference>
            <spring_stiffness>0</spring_stiffness>
          </dynamics>
        </axis>
      </joint>
      <link name='wheel_forward_left_link'>
        <pose relative_to='wheel_forward_left_joint'>0 0 0 0 -0 0</pose>
        <inertial>
          <pose>0 0 0 0 -0 0</pose>
          <mass>4.1</mass>
          <inertia>
            <ixx>1.24701</ixx>
            <ixy>0</ixy>
            <ixz>0</ixz>
            <iyy>1.90173</iyy>
            <iyz>0</iyz>
            <izz>1.24574</izz>
          </inertia>
        </inertial>
        <collision name='wheel_forward_left_link_collision'>
          <pose>0 0 0 0 -0 0</pose>
          <geometry>
            <mesh>
              <scale>1 1 1</scale>
              <uri>model://potrol_description_cmake/meshes/wheel.dae</uri>
            </mesh>
          </geometry>
          <surface>
            <contact>
              <ode/>
            </contact>
            <friction>
              <ode>
                <mu2>1</mu2>
              </ode>
              <torsional>
                <ode/>
              </torsional>
            </friction>
            <bounce/>
          </surface>
          <max_contacts>10</max_contacts>
        </collision>
        <visual name='wheel_forward_left_link_visual'>
          <pose>0 0 0 0 -0 0</pose>
          <geometry>
            <mesh>
              <scale>1 1 1</scale>
              <uri>model://potrol_description_cmake/meshes/wheel.dae</uri>
            </mesh>
          </geometry>
          <material>
            <script>
              <name>Gazebo/Gray</name>
              <uri>file://media/materials/scripts/gazebo.material</uri>
            </script>
          </material>
        </visual>
        <self_collide>0</self_collide>
        <enable_wind>0</enable_wind>
        <kinematic>0</kinematic>
        <mu>1.0</mu>
      </link>
      <joint name='wheel_connnect_frame_forward_right_joint' type='revolute'>
        <pose relative_to='base_link'>0.307287 -0.170165 0.032513 0 -0 0</pose>
        <parent>base_link</parent>
        <child>wheel_connnect_frame_forward_right_link</child>
        <axis>
          <xyz>0 0 1</xyz>
          <limit>
            <lower>-1e+16</lower>
            <upper>1e+16</upper>
          </limit>
          <dynamics>
            <spring_reference>0</spring_reference>
            <spring_stiffness>0</spring_stiffness>
          </dynamics>
        </axis>
      </joint>
      <link name='wheel_connnect_frame_forward_right_link'>
        <pose relative_to='wheel_connnect_frame_forward_right_joint'>0 0 0 0 -0 0</pose>
        <inertial>
          <pose>0 0 0 0 -0 0</pose>
          <mass>1</mass>
          <inertia>
            <ixx>0.631229</ixx>
            <ixy>0</ixy>
            <ixz>0</ixz>
            <iyy>0.631229</iyy>
            <iyz>0</iyz>
            <izz>1.15312</izz>
          </inertia>
        </inertial>
        <collision name='wheel_connnect_frame_forward_right_link_collision'>
          <pose>0 0 0 0 -0 0</pose>
          <geometry>
            <mesh>
              <scale>1 1 1</scale>
              <uri>model://potrol_description_cmake/meshes/connnect_frame.dae</uri>
            </mesh>
          </geometry>
          <max_contacts>10</max_contacts>
          <surface>
            <contact>
              <ode/>
            </contact>
            <bounce/>
            <friction>
              <torsional>
                <ode/>
              </torsional>
              <ode/>
            </friction>
          </surface>
        </collision>
        <visual name='wheel_connnect_frame_forward_right_link_visual'>
          <pose>0 0 0 0 -0 0</pose>
          <geometry>
            <mesh>
              <scale>1 1 1</scale>
              <uri>model://potrol_description_cmake/meshes/connnect_frame.dae</uri>
            </mesh>
          </geometry>
        </visual>
        <self_collide>0</self_collide>
        <enable_wind>0</enable_wind>
        <kinematic>0</kinematic>
      </link>
      <joint name='wheel_forward_right_joint' type='revolute'>
        <pose relative_to='wheel_connnect_frame_forward_right_link'>0 -0.05 0 0 -0 0</pose>
        <parent>wheel_connnect_frame_forward_right_link</parent>
        <child>wheel_forward_right_link</child>
        <axis>
          <xyz>0 1 0</xyz>
          <limit>
            <lower>-1e+16</lower>
            <upper>1e+16</upper>
          </limit>
          <dynamics>
            <spring_reference>0</spring_reference>
            <spring_stiffness>0</spring_stiffness>
          </dynamics>
        </axis>
      </joint>
      <link name='wheel_forward_right_link'>
        <pose relative_to='wheel_forward_right_joint'>0 0 0 0 -0 0</pose>
        <inertial>
          <pose>0 0 0 0 -0 0</pose>
          <mass>4.1</mass>
          <inertia>
            <ixx>1.24701</ixx>
            <ixy>0</ixy>
            <ixz>0</ixz>
            <iyy>1.90173</iyy>
            <iyz>0</iyz>
            <izz>1.24574</izz>
          </inertia>
        </inertial>
        <collision name='wheel_forward_right_link_collision'>
          <pose>0 0 0 0 -0 0</pose>
          <geometry>
            <mesh>
              <scale>1 1 1</scale>
              <uri>model://potrol_description_cmake/meshes/wheel.dae</uri>
            </mesh>
          </geometry>
          <surface>
            <contact>
              <ode/>
            </contact>
            <friction>
              <ode>
                <mu2>1</mu2>
              </ode>
              <torsional>
                <ode/>
              </torsional>
            </friction>
            <bounce/>
          </surface>
          <max_contacts>10</max_contacts>
        </collision>
        <visual name='wheel_forward_right_link_visual'>
          <pose>0 0 0 0 -0 0</pose>
          <geometry>
            <mesh>
              <scale>1 1 1</scale>
              <uri>model://potrol_description_cmake/meshes/wheel.dae</uri>
            </mesh>
          </geometry>
          <material>
            <script>
              <name>Gazebo/Gray</name>
              <uri>file://media/materials/scripts/gazebo.material</uri>
            </script>
          </material>
        </visual>
        <self_collide>0</self_collide>
        <enable_wind>0</enable_wind>
        <kinematic>0</kinematic>
        <mu>1.0</mu>
      </link>
      <plugin name='potrol_gazebo_ros2_control' filename='libgazebo_ros2_control.so'>
        <parameters>/home/nurmukk/Nurmukhan/ros2_project/potrol_robot/install/potrol_bringup/share/potrol_bringup/config/controller_configuration.yaml</parameters>
      </plugin>
      <frame name='camera_optical_joint' attached_to='camera_link'>
        <pose>0 0 0 -1.5708 -0 -1.5708</pose>
      </frame>
      <frame name='camera_link_optical' attached_to='camera_optical_joint'/>
      <frame name='camera_joint' attached_to='base_link'>
        <pose>0.37 -0.004 0.035 0 -0 0</pose>
      </frame>
      <frame name='camera_link' attached_to='camera_joint'/>
      <pose>0 0 0 0 -0 0</pose>
    </model>
  </world>
</sdf>
