<?xml version="1.0" ?>
<!-- =================================================================================== -->
<!-- |    This document was autogenerated by xacro from /home/nurmukk/Nurmukhan/ros2_project/potrol_robot/src/potrol_description_cmake/urdf/potrol_diff_drive.xacro | -->
<!-- |    EDITING THIS FILE BY HAND IS NOT RECOMMENDED                                 | -->
<!-- =================================================================================== -->
<robot name="potrol">
  <material name="Blue">
    <color rgba="0.03 0.01 0.97 1"/>
  </material>
  <material name="Yellow">
    <color rgba="0.82 0.8 0.08 1"/>
  </material>
  <material name="Black">
    <color rgba="0.27 0.27 0.27 1"/>
  </material>
  <material name="gray2">
    <color rgba="0.76 0.76 0.76 1"/>
  </material>
  <material name="gray">
    <color rgba="0.76 0.76 0.76 1"/>
  </material>
  <link name="base_footprint"> 
    </link>
  <!-- BASE LINK -->
  <link name="base_link">
    <inertial>
      <origin rpy="0.0 0.0 1.57" xyz="0.0 0.0 0.58"/>
      <mass value="10.0"/>
      <inertia ixx="0.544083333333" ixy="0" ixz="0" iyy="0.544083333333" iyz="0" izz="0.384"/>
    </inertial>
    <visual>
      <origin rpy="0 0 1.57" xyz="0 0 0"/>
      <geometry>
        <!-- <box size="0.48 0.48 0.650"/> -->
        <mesh filename="package://potrol_description_cmake/meshes/robo_frame.stl" scale="0.75 0.75 0.75"/>
      </geometry>
      <material name="gray"/>
    </visual>
    <collision>
      <origin rpy="0 0 1.57" xyz="0 0 0"/>
      <geometry>
        <!-- <box size="0.48 0.48 0.650"/> -->
        <mesh filename="package://potrol_description_cmake/meshes/robo_frame.stl" scale="0.75 0.75 0.75"/>
      </geometry>
    </collision>
  </link>
  <joint name="base_joint" type="fixed">
    <origin rpy="0.0 0.0 0" xyz="0.0 0.0 0.03"/>
    <!-- <origin xyz="0.0 0.0 0.42" rpy="0.0 0.0 1.57"/> -->
    <parent link="base_footprint"/>
    <child link="base_link"/>
    <axis xyz="0.0 0.0 0"/>
  </joint>
  <!-- BASE LINK END -->
  <!-- CAMERA -->
  <joint name="camera_joint" type="fixed">
    <parent link="base_link"/>
    <child link="camera_link"/>
    <origin rpy="0 0 0" xyz="0.249564 -0.0 0.227776"/>
  </joint>
  <!-- CAMERA END -->
  <!-- LiDAR -->
  <joint name="laser_joint" type="fixed">
    <parent link="base_link"/>
    <child link="laser_frame"/>
    <origin rpy="0 0 0" xyz="0.156491 0.0 0.813175"/>
  </joint>
  <link name="laser_frame">
    <visual>
      <geometry>
        <cylinder length="0.04" radius="0.0375"/>
      </geometry>
      <material name="Black"/>
    </visual>
    <collision>
      <geometry>
        <cylinder length="0.03" radius="0.0375"/>
      </geometry>
    </collision>
    <inertial>
      <origin rpy="0.0 0.0 0.0" xyz="0.0 0.0 0.0"/>
      <mass value="0.1"/>
      <inertia ixx="1.01633333333" ixy="0" ixz="0" iyy="1.01633333333" iyz="0" izz="0.682666666667"/>
    </inertial>
  </link>
  <!-- LiDAR END -->
  <!-- WHEEL -->
  <link name="wheel_forward_left_link">
    <inertial>
      <origin rpy="0.0 0.0 0.0" xyz="0.0 0.0 0.0"/>
      <mass value="4.1"/>
      <inertia ixx="0.00631229166667" ixy="0" ixz="0" iyy="0.00631229166667" iyz="0" izz="0.01153125"/>
    </inertial>
    <visual>
      <geometry>
        <cylinder length="0.04" radius="0.075"/>
      </geometry>
      <material name="Black"/>
    </visual>
    <collision>
      <geometry>
        <cylinder length="0.038" radius="0.075"/>
      </geometry>
    </collision>
  </link>
  <gazebo reference="wheel_forward_left_link">
    <material>Gazebo/Gray</material>
    <mu1>1000000000000.0</mu1>
    <mu2>1000000000000.0</mu2>
    <!-- <kp>10000000000.0</kp>
          <kp>10.0</kp> -->
    <!-- <minDepth>0.001</minDepth> -->
  </gazebo>
  <joint name="wheel_forward_left_joint" type="continuous">
    <origin rpy="-1.57 0 0" xyz="0.21375 0.26775 0.1"/>
    <parent link="base_footprint"/>
    <child link="wheel_forward_left_link"/>
    <axis xyz="0.0 0.0 1.0"/>
  </joint>
  <!-- <transmission name="wheel_${name}_transmission">
            <type>transmission_interface/SimpleTransmission</type>
            <joint name="wheel_${name}_joint">
              <hardwareInterface>hardware_interface/VelocityJointInterface</hardwareInterface>
            </joint>
            <actuator name="wheel_${name}_motor">
              <hardwareInterface>VelocityJointInterface</hardwareInterface>
              <mechanicalReduction>1</mechanicalReduction>
            </actuator>
        </transmission>
        <gazebo reference="wheel_${name}_link">
          <material>Gazebo/Gray</material>
          <mu1>1000000000000.0</mu1>
          <mu2>1000000000000.0</mu2> -->
  <!-- <kp>10000000000.0</kp>
          <kp>10.0</kp> -->
  <!-- <minDepth>0.001</minDepth> -->
  <!-- </gazebo> -->
  <link name="wheel_forward_right_link">
    <inertial>
      <origin rpy="0.0 0.0 0.0" xyz="0.0 0.0 0.0"/>
      <mass value="4.1"/>
      <inertia ixx="0.00631229166667" ixy="0" ixz="0" iyy="0.00631229166667" iyz="0" izz="0.01153125"/>
    </inertial>
    <visual>
      <geometry>
        <cylinder length="0.04" radius="0.075"/>
      </geometry>
      <material name="Black"/>
    </visual>
    <collision>
      <geometry>
        <cylinder length="0.038" radius="0.075"/>
      </geometry>
    </collision>
  </link>
  <gazebo reference="wheel_forward_right_link">
    <material>Gazebo/Gray</material>
    <mu1>1000000000000.0</mu1>
    <mu2>1000000000000.0</mu2>
    <!-- <kp>10000000000.0</kp>
          <kp>10.0</kp> -->
    <!-- <minDepth>0.001</minDepth> -->
  </gazebo>
  <joint name="wheel_forward_right_joint" type="continuous">
    <origin rpy="-1.57 0 0" xyz="0.21375 -0.26775 0.1"/>
    <parent link="base_footprint"/>
    <child link="wheel_forward_right_link"/>
    <axis xyz="0.0 0.0 1.0"/>
  </joint>
  <!-- <transmission name="wheel_${name}_transmission">
            <type>transmission_interface/SimpleTransmission</type>
            <joint name="wheel_${name}_joint">
              <hardwareInterface>hardware_interface/VelocityJointInterface</hardwareInterface>
            </joint>
            <actuator name="wheel_${name}_motor">
              <hardwareInterface>VelocityJointInterface</hardwareInterface>
              <mechanicalReduction>1</mechanicalReduction>
            </actuator>
        </transmission>
        <gazebo reference="wheel_${name}_link">
          <material>Gazebo/Gray</material>
          <mu1>1000000000000.0</mu1>
          <mu2>1000000000000.0</mu2> -->
  <!-- <kp>10000000000.0</kp>
          <kp>10.0</kp> -->
  <!-- <minDepth>0.001</minDepth> -->
  <!-- </gazebo> -->
  <link name="wheel_back_right_link">
    <inertial>
      <origin rpy="0.0 0.0 0.0" xyz="0.0 0.0 0.0"/>
      <mass value="4.1"/>
      <inertia ixx="0.00631229166667" ixy="0" ixz="0" iyy="0.00631229166667" iyz="0" izz="0.01153125"/>
    </inertial>
    <visual>
      <geometry>
        <cylinder length="0.04" radius="0.075"/>
      </geometry>
      <material name="Black"/>
    </visual>
    <collision>
      <geometry>
        <cylinder length="0.038" radius="0.075"/>
      </geometry>
    </collision>
  </link>
  <gazebo reference="wheel_back_right_link">
    <material>Gazebo/Gray</material>
    <mu1>1000000000000.0</mu1>
    <mu2>1000000000000.0</mu2>
    <!-- <kp>10000000000.0</kp>
          <kp>10.0</kp> -->
    <!-- <minDepth>0.001</minDepth> -->
  </gazebo>
  <joint name="wheel_back_right_joint" type="continuous">
    <origin rpy="-1.57 0 0" xyz="-0.21375 -0.26775 0.1"/>
    <parent link="base_footprint"/>
    <child link="wheel_back_right_link"/>
    <axis xyz="0.0 0.0 1.0"/>
  </joint>
  <!-- <transmission name="wheel_${name}_transmission">
            <type>transmission_interface/SimpleTransmission</type>
            <joint name="wheel_${name}_joint">
              <hardwareInterface>hardware_interface/VelocityJointInterface</hardwareInterface>
            </joint>
            <actuator name="wheel_${name}_motor">
              <hardwareInterface>VelocityJointInterface</hardwareInterface>
              <mechanicalReduction>1</mechanicalReduction>
            </actuator>
        </transmission>
        <gazebo reference="wheel_${name}_link">
          <material>Gazebo/Gray</material>
          <mu1>1000000000000.0</mu1>
          <mu2>1000000000000.0</mu2> -->
  <!-- <kp>10000000000.0</kp>
          <kp>10.0</kp> -->
  <!-- <minDepth>0.001</minDepth> -->
  <!-- </gazebo> -->
  <link name="wheel_back_left_link">
    <inertial>
      <origin rpy="0.0 0.0 0.0" xyz="0.0 0.0 0.0"/>
      <mass value="4.1"/>
      <inertia ixx="0.00631229166667" ixy="0" ixz="0" iyy="0.00631229166667" iyz="0" izz="0.01153125"/>
    </inertial>
    <visual>
      <geometry>
        <cylinder length="0.04" radius="0.075"/>
      </geometry>
      <material name="Black"/>
    </visual>
    <collision>
      <geometry>
        <cylinder length="0.038" radius="0.075"/>
      </geometry>
    </collision>
  </link>
  <gazebo reference="wheel_back_left_link">
    <material>Gazebo/Gray</material>
    <mu1>1000000000000.0</mu1>
    <mu2>1000000000000.0</mu2>
    <!-- <kp>10000000000.0</kp>
          <kp>10.0</kp> -->
    <!-- <minDepth>0.001</minDepth> -->
  </gazebo>
  <joint name="wheel_back_left_joint" type="continuous">
    <origin rpy="-1.57 0 0" xyz="-0.21375 0.26775 0.1"/>
    <parent link="base_footprint"/>
    <child link="wheel_back_left_link"/>
    <axis xyz="0.0 0.0 1.0"/>
  </joint>
  <!-- <transmission name="wheel_${name}_transmission">
            <type>transmission_interface/SimpleTransmission</type>
            <joint name="wheel_${name}_joint">
              <hardwareInterface>hardware_interface/VelocityJointInterface</hardwareInterface>
            </joint>
            <actuator name="wheel_${name}_motor">
              <hardwareInterface>VelocityJointInterface</hardwareInterface>
              <mechanicalReduction>1</mechanicalReduction>
            </actuator>
        </transmission>
        <gazebo reference="wheel_${name}_link">
          <material>Gazebo/Gray</material>
          <mu1>1000000000000.0</mu1>
          <mu2>1000000000000.0</mu2> -->
  <!-- <kp>10000000000.0</kp>
          <kp>10.0</kp> -->
  <!-- <minDepth>0.001</minDepth> -->
  <!-- </gazebo> -->
  <!-- <joint name="camera_joint" type="fixed">
        <parent link="base_link"/>
        <child link="camera_link"/>
        <origin xyz="0.37 -0.004 0.035" rpy="0 0 0"/>
    </joint> -->
  <link name="camera_link">
    <visual>
      <geometry>
        <box size="0.010 0.03 0.03"/>
      </geometry>
      <material name="red"/>
    </visual>
  </link>
  <joint name="camera_optical_joint" type="fixed">
    <parent link="camera_link"/>
    <child link="camera_link_optical"/>
    <origin rpy="-1.5707963267948966 0 -1.5707963267948966" xyz="0 0 0"/>
  </joint>
  <link name="camera_link_optical"/>
  <gazebo reference="camera_link">
    <material>Gazebo/Red</material>
    <sensor name="camera" type="depth">
      <pose> 0 0 0 0 0 0 </pose>
      <visualize>true</visualize>
      <update_rate>10</update_rate>
      <camera>
        <horizontal_fov>1.089</horizontal_fov>
        <image>
          <format>B8G8R8</format>
          <width>640</width>
          <height>480</height>
        </image>
        <clip>
          <near>0.05</near>
          <far>8.0</far>
        </clip>
      </camera>
      <plugin filename="libgazebo_ros_camera.so" name="camera_controller">
        <frame_name>camera_link_optical</frame_name>
        <min_depth>0.1</min_depth>
        <max_depth>100.0</max_depth>
      </plugin>
    </sensor>
  </gazebo>
  <!-- camera -->
  <!-- <xacro:macro name="camera" params="link_name">

    <joint name="${link_name}_joint" type="fixed">
        <axis xyz="0 1 0" />
        <origin xyz="0.333633 -0.006 0.1443382" rpy="0 0 0"/>
        <parent link="base_link"/>
        <child link="${link_name}"/>
    </joint> -->
  <!-- Camera -->
  <!-- <link name="${link_name}">
        <collision>
            <origin xyz="0 0 0" rpy="0 0 1.57"/>
            <geometry>
                <mesh filename="package://potrol_description_cmake/stl/ZED2i.stl" scale="0.001 0.001 0.001"/>
            </geometry>
        </collision>

        <visual>
            <origin xyz="0 0 0" rpy="0 0 1.57"/>
            <geometry>
                <mesh filename="package://potrol_description_cmake/stl/ZED2i.stl" scale="0.001 0.001 0.001"/>

            </geometry>
        </visual>

        <inertial>
            <mass value="1e-5" />
            <origin xyz="0 0 0" rpy="0 0 0"/>
            <inertia ixx="1e-6" ixy="0" ixz="0" iyy="1e-6" iyz="0" izz="1e-6" />
        </inertial>
    </link>
    <gazebo reference="${link_name}">
        <sensor name="${link_name}_sens" type="depth">
            <update_rate>50</update_rate>
            <camera>
                <horizontal_fov>1.047198</horizontal_fov>
                <image>
                    <width>640</width>
                    <height>480</height>
                    <format>R8G8B8</format>
                </image>
                <clip>
                    <near>0.05</near>
                    <far>3</far>
                </clip>
            </camera>
            <plugin name="${link_name}_controller" filename="libgazebo_ros_openni_kinect.so">
            <baseline>0.2</baseline>
            <alwaysOn>true</alwaysOn>
            <updateRate>1.0</updateRate>
            <cameraName>${link_name}</cameraName>
            <imageTopicName>/${link_name}/color/image_raw</imageTopicName>
            <cameraInfoTopicName>/${link_name}/color/camera_info</cameraInfoTopicName>
            <depthImageTopicName>/${link_name}/depth/image_raw</depthImageTopicName>
            <depthImageInfoTopicName>/${link_name}/depth/camera_info</depthImageInfoTopicName>
            <pointCloudTopicName>/${link_name}/depth/points</pointCloudTopicName>
            <frameName>${link_name}_frame</frameName>
            <pointCloudCutoff>0.5</pointCloudCutoff>
            <pointCloudCutoffMax>3.0</pointCloudCutoffMax>
            <distortionK1>0.00000001</distortionK1>
            <distortionK2>0.00000001</distortionK2>
            <distortionK3>0.00000001</distortionK3>
            <distortionT1>0.00000001</distortionT1>
            <distortionT2>0.00000001</distortionT2>
            <CxPrime>0</CxPrime>
            <Cx>0</Cx>
            <Cy>0</Cy>
            <focalLength>0</focalLength>
            <hackBaseline>0</hackBaseline>
            </plugin>
        </sensor>
    </gazebo>
</xacro:macro>

<xacro:camera link_name="ZED2i"/>  -->
  <!-- lidar <link name="laser_frame"> -->
  <gazebo reference="laser_frame">
    <material>Gazebo/Black</material>
    <sensor name="laser" type="ray">
      <pose> 0 0 0 0 0 0 </pose>
      <visualize>false</visualize>
      <update_rate>10</update_rate>
      <ray>
        <scan>
          <horizontal>
            <samples>360</samples>
            <min_angle>-3.14</min_angle>
            <max_angle>3.14</max_angle>
          </horizontal>
        </scan>
        <range>
          <min>0.3</min>
          <max>12</max>
        </range>
      </ray>
      <plugin filename="libgazebo_ros_ray_sensor.so" name="laser_controller">
        <ros>
          <argument>~/out:=scan</argument>
        </ros>
        <output_type>sensor_msgs/LaserScan</output_type>
        <frame_name>laser_frame</frame_name>
      </plugin>
    </sensor>
  </gazebo>
  <ros2_control name="GazeboSystem" type="system">
    <hardware>
      <plugin>gazebo_ros2_control/GazeboSystem</plugin>
    </hardware>
    <joint name="wheel_forward_right_joint">
      <command_interface name="velocity">
        <param name="min">-5</param>
        <param name="max">5</param>
      </command_interface>
      <state_interface name="position"/>
      <state_interface name="velocity"/>
    </joint>
    <joint name="wheel_forward_left_joint">
      <command_interface name="velocity">
        <param name="min">-5</param>
        <param name="max">5</param>
      </command_interface>
      <state_interface name="position"/>
      <state_interface name="velocity"/>
    </joint>
    <joint name="wheel_back_right_joint">
      <command_interface name="velocity">
        <param name="min">-5</param>
        <param name="max">5</param>
      </command_interface>
      <state_interface name="position"/>
      <state_interface name="velocity"/>
    </joint>
    <joint name="wheel_back_left_joint">
      <command_interface name="velocity">
        <param name="min">-5</param>
        <param name="max">5</param>
      </command_interface>
      <state_interface name="position"/>
      <state_interface name="velocity"/>
    </joint>
    <!-- <joint name="wheel_forward_right_joint">
            <command_interface name="velocity">
              <param name="min">-5</param>
              <param name="max">5</param>
            </command_interface>
            <state_interface name="position"/>
            <state_interface name="velocity"/>
          </joint>

          <joint name="wheel_forward_left_joint">
            <command_interface name="velocity">
              <param name="min">-5</param>
              <param name="max">5</param>
            </command_interface>
            <state_interface name="position"/>
            <state_interface name="velocity"/>
          </joint>
          
          <joint name="wheel_backward_right_joint">
            <command_interface name="velocity">
              <param name="min">-5</param>
              <param name="max">5</param>
            </command_interface>
            <state_interface name="position"/>
            <state_interface name="velocity"/>
          </joint>
          
          <joint name="wheel_backward_left_joint">
            <command_interface name="velocity">
              <param name="min">-5</param>
              <param name="max">5</param>
            </command_interface>
            <state_interface name="position"/>
            <state_interface name="velocity"/>
          </joint> -->
  </ros2_control>
  <gazebo>
    <plugin filename="libgazebo_ros2_control.so" name="gazebo_ros2_control">
      <parameters>/home/nurmukk/Nurmukhan/ros2_project/potrol_robot/install/potrol_bringup/share/potrol_bringup/config/controller_configuration_diff_drive.yaml</parameters>
    </plugin>
  </gazebo>
  <!-- <xacro:include filename="camera2.xacro"/> -->
</robot>
