<?xml version="1.0" encoding="utf-8"?>
<!-- =================================================================================== -->
<!-- |    This document was autogenerated by xacro from agrobot_diagonal_wheels_angular.xacro | -->
<!-- |    EDITING THIS FILE BY HAND IS NOT RECOMMENDED                                 | -->
<!-- =================================================================================== -->
<robot name="agro">
  <link name="base_footprint"> 
    </link>
  <!-- BASE LINK -->
  <link name="base_link">
    <visual name="solar_panel_back">
      <origin rpy="0 -0.66 0" xyz="-0.65 0 0.86"/>
      <geometry>
        <box size="0.4 0.8 0.02"/>
      </geometry>
      <material name="blue">
        <color rgba="0.03 0.01 0.97 1"/>
      </material>
    </visual>
    <collision name="solar_panel_back">
      <origin rpy="0 -0.66 0" xyz="-0.65 0 0.86"/>
      <geometry>
        <box size="0.4 0.8 0.02"/>
      </geometry>
    </collision>
    <visual name="solar_panel_big">
      <origin rpy="0 0 0" xyz="0 0 0.98"/>
      <geometry>
        <box size="1 0.8 0.02"/>
      </geometry>
      <material name="blue">
        <color rgba="0.03 0.01 0.97 1"/>
      </material>
    </visual>
    <collision name="solar_panel_big">
      <origin rpy="0 0 0" xyz="0 0 0.98"/>
      <geometry>
        <box size="1 0.8 0.02"/>
      </geometry>
    </collision>
    <visual name="solar_panel_forward">
      <origin rpy="0 0.66 0" xyz="0.65 0 0.86"/>
      <geometry>
        <box size="0.4 0.8 0.02"/>
      </geometry>
      <material name="blue">
        <color rgba="0.03 0.01 0.97 1"/>
      </material>
    </visual>
    <collision name="solar_panel_forward">
      <origin rpy="0 0.66 0" xyz="0.65 0 0.86"/>
      <geometry>
        <box size="0.4 0.8 0.02"/>
      </geometry>
    </collision>
    <visual name="frame1">
      <origin rpy="0 0 0" xyz="0. 0.4 0.74"/>
      <geometry>
        <box size="1.6 0.02 0.02"/>
      </geometry>
      <material name="gray">
        <color rgba="0.76 0.76 0.76 1"/>
      </material>
    </visual>
    <collision name="frame1">
      <origin rpy="0 0 0" xyz="0. 0.4 0.74"/>
      <geometry>
        <box size="1.6 0.02 0.02"/>
      </geometry>
    </collision>
    <visual name="frame2">
      <origin rpy="0 0 0" xyz="0. -0.4 0.74"/>
      <geometry>
        <box size="1.6 0.02 0.02"/>
      </geometry>
      <material name="gray">
        <color rgba="0.76 0.76 0.76 1"/>
      </material>
    </visual>
    <collision name="frame2">
      <origin rpy="0 0 0" xyz="0. -0.4 0.74"/>
      <geometry>
        <box size="1.6 0.02 0.02"/>
      </geometry>
    </collision>
    <visual name="frame3">
      <origin rpy="0 0 0" xyz="0. 0.4 0.59"/>
      <geometry>
        <box size="1.6 0.02 0.02"/>
      </geometry>
      <material name="gray">
        <color rgba="0.76 0.76 0.76 1"/>
      </material>
    </visual>
    <collision name="frame3">
      <origin rpy="0 0 0" xyz="0. 0.4 0.59"/>
      <geometry>
        <box size="1.6 0.02 0.02"/>
      </geometry>
    </collision>
    <visual name="frame_center">
      <origin rpy="0 0 0" xyz="0.51 0 0.59"/>
      <geometry>
        <box size="0.56 0.8 0.001"/>
      </geometry>
      <material name="yellow">
        <color rgba="0.82 0.8 0.08 1"/>
      </material>
    </visual>
    <collision name="frame_center">
      <origin rpy="0 0 0" xyz="0.51 0 0.59"/>
      <geometry>
        <box size="0.56 0.8 0.001"/>
      </geometry>
    </collision>
    <visual name="frame4">
      <origin rpy="0 0 0" xyz="0. -0.4 0.59"/>
      <geometry>
        <box size="1.6 0.02 0.02"/>
      </geometry>
      <material name="gray">
        <color rgba="0.76 0.76 0.76 1"/>
      </material>
    </visual>
    <collision name="frame4">
      <origin rpy="0 0 0" xyz="0. -0.4 0.59"/>
      <geometry>
        <box size="1.6 0.02 0.02"/>
      </geometry>
    </collision>
    <visual name="frame5">
      <origin rpy="0 0 0" xyz="0.8 0 0.59"/>
      <geometry>
        <box size="0.02 0.8 0.02"/>
      </geometry>
      <material name="gray">
        <color rgba="0.76 0.76 0.76 1"/>
      </material>
    </visual>
    <collision name="frame5">
      <origin rpy="0 0 0" xyz="0.8 0 0.59"/>
      <geometry>
        <box size="0.02 0.8 0.02"/>
      </geometry>
    </collision>
    <visual name="frame6">
      <origin rpy="0 0 0" xyz="-0.8 0 0.59"/>
      <geometry>
        <box size="0.02 0.8 0.02"/>
      </geometry>
      <material name="gray">
        <color rgba="0.76 0.76 0.76 1"/>
      </material>
    </visual>
    <collision name="frame6">
      <origin rpy="0 0 0" xyz="-0.8 0 0.59"/>
      <geometry>
        <box size="0.02 0.8 0.02"/>
      </geometry>
    </collision>
    <visual name="frame_wheel_b_l">
      <origin rpy="0 0 0" xyz="-0.785 0.4 0.41"/>
      <geometry>
        <box size="0.05 0.02 0.64"/>
      </geometry>
      <material name="gray">
        <color rgba="0.76 0.76 0.76 1"/>
      </material>
    </visual>
    <collision name="frame_wheel_b_l">
      <origin rpy="0 0 0" xyz="-0.785 0.4 0.41"/>
      <geometry>
        <box size="0.05 0.02 0.64"/>
      </geometry>
    </collision>
    <visual name="frame_wheel_f_r">
      <origin rpy="0 0 0" xyz="0.785 -0.4 0.41"/>
      <geometry>
        <box size="0.05 0.02 0.64"/>
      </geometry>
      <material name="gray">
        <color rgba="0.76 0.76 0.76 1"/>
      </material>
    </visual>
    <collision name="frame_wheel_f_r">
      <origin rpy="0 0 0" xyz="0.785 -0.4 0.41"/>
      <geometry>
        <box size="0.05 0.02 0.64"/>
      </geometry>
    </collision>
    <collision>
      <origin rpy="0 0 0" xyz="0.0 0.0 0.85"/>
      <geometry>
        <box size="1 0.8 0.25"/>
      </geometry>
    </collision>
    <inertial>
      <origin rpy="0.0 0.0 0.0" xyz="0.0 0.0 0.0"/>
      <mass value="40.0"/>
      <inertia ixx="11.7346" ixy="0.0" ixz="0.0" iyy="9.06" iyz="0.0" izz="3.73"/>
    </inertial>
  </link>
  <joint name="base_joint" type="fixed">
    <origin rpy="0.0 0.0 0.0" xyz="0.0 0.0 0.0"/>
    <parent link="base_footprint"/>
    <child link="base_link"/>
    <axis xyz="0.0 0.0 0.0"/>
  </joint>
  <link name="frame_wheel_forward_left">
    <visual name="frame_wheel_b_r">
      <!-- <origin rpy="0 0 0" xyz="-0.785 -0.4 0.485"/> -->
      <geometry>
        <box size="0.05 0.02 0.52"/>
      </geometry>
      <material name="gray">
        <color rgba="0.76 0.76 0.76 1"/>
      </material>
    </visual>
    <collision>
      <!-- <origin rpy="0 0 0" xyz="-0.785 -0.4 0.485"/> -->
      <geometry>
        <box size="0.05 0.02 0.52"/>
      </geometry>
    </collision>
    
            v
    <inertial>
      <origin rpy="0.0 0.0 0.0" xyz="0.0 0.0 0.0"/>
      <mass value="1.0"/>
      <inertia ixx="0.0227417" ixy="0.0" ixz="0.0" iyy="0.000241667" iyz="0.0" izz="0.0225667"/>
    </inertial>
  </link>
  <!-- revolute continuous -->
  <joint name="frame_wheel_forward_left_joint" type="revolute">
    <origin rpy="0.0 0.0 0.0" xyz="0.785 0.4 0.485"/>
    <parent link="base_link"/>
    <child link="frame_wheel_forward_left"/>
    <axis xyz="0.0 0.0 1.0"/>
    <limit effort="100.0" lower="1.0" upper="2.0" velocity="1.57"/>
  </joint>
  <link name="frame_wheel_back_right">
    <visual name="frame_wheel_b_r">
      <!-- <origin rpy="0 0 0" xyz="-0.785 -0.4 0.485"/> -->
      <geometry>
        <box size="0.05 0.02 0.52"/>
      </geometry>
      <material name="gray">
        <color rgba="0.76 0.76 0.76 1"/>
      </material>
    </visual>
    <collision>
      <!-- <origin rpy="0 0 0" xyz="-0.785 -0.4 0.485"/> -->
      <geometry>
        <box size="0.05 0.02 0.52"/>
      </geometry>
    </collision>
    
            v
    <inertial>
      <origin rpy="0.0 0.0 0.0" xyz="0.0 0.0 0.0"/>
      <mass value="1.0"/>
      <inertia ixx="0.0227417" ixy="0.0" ixz="0.0" iyy="0.000241667" iyz="0.0" izz="0.0225667"/>
    </inertial>
  </link>
  <!-- revolute continuous -->
  <joint name="frame_wheel_back_right_joint" type="revolute">
    <origin rpy="0.0 0.0 0.0" xyz="-0.785 -0.4 0.485"/>
    <parent link="base_link"/>
    <child link="frame_wheel_back_right"/>
    <axis xyz="0.0 0.0 1.0"/>
    <limit effort="100.0" lower="1.0" upper="2.0" velocity="1.57"/>
  </joint>
  <!-- lower - минимальное значение угла поворота (в радианах).
        upper - максимальное значение угла поворота (в радианах).
        velocity - максимальная скорость поворота сустава (в радианах в секунду).
        effort - максимальное усилие, которое может быть применено к суставу (в Ньютонах). -->
  <!-- swivel frame end -->
  <!-- WHEEL -->
  <link name="wheel_forward_left_link">
    <inertial>
      <origin rpy="0.0 0.0 0.0" xyz="0.0 0.0 0.0"/>
      <mass value="4.1"/>
      <inertia ixx="0.0267867" ixy="0.0" ixz="0.0" iyy="0.0267867" iyz="0.0" izz="2.10248"/>
    </inertial>
    <visual name="wheel_b">
      <!-- <origin rpy="1.57 0 0" xyz="0.785 0.43 0.16"/> -->
      <geometry>
        <cylinder length="0.04" radius="0.16"/>
      </geometry>
      <material name="black">
        <color rgba="0.27 0.27 0.27 1"/>
      </material>
    </visual>
    <collision>
      <!-- <origin rpy="1.57 0 0" xyz="0.785 0.43 0.16"/> -->
      <geometry>
        <cylinder length="0.04" radius="0.16"/>
      </geometry>
      <material name="black">
        <color rgba="0.27 0.27 0.27 1"/>
      </material>
    </collision>
  </link>
  <joint name="wheel_forward_left_joint" type="continuous">
    <origin rpy="-1.57 0 0" xyz="0.0 0.03 -0.325"/>
    <parent link="frame_wheel_forward_left"/>
    <child link="wheel_forward_left_link"/>
    <axis xyz="0.0 0.0 1.0"/>
  </joint>
  <link name="wheel_back_right_link">
    <inertial>
      <origin rpy="0.0 0.0 0.0" xyz="0.0 0.0 0.0"/>
      <mass value="4.1"/>
      <inertia ixx="0.0267867" ixy="0.0" ixz="0.0" iyy="0.0267867" iyz="0.0" izz="2.10248"/>
    </inertial>
    <visual name="wheel_b">
      <!-- <origin rpy="1.57 0 0" xyz="0.785 0.43 0.16"/> -->
      <geometry>
        <cylinder length="0.04" radius="0.16"/>
      </geometry>
      <material name="black">
        <color rgba="0.27 0.27 0.27 1"/>
      </material>
    </visual>
    <collision>
      <!-- <origin rpy="1.57 0 0" xyz="0.785 0.43 0.16"/> -->
      <geometry>
        <cylinder length="0.04" radius="0.16"/>
      </geometry>
      <material name="black">
        <color rgba="0.27 0.27 0.27 1"/>
      </material>
    </collision>
  </link>
  <joint name="wheel_back_right_joint" type="continuous">
    <origin rpy="-1.57 0 0" xyz="0.0 -0.03 -0.325"/>
    <parent link="frame_wheel_back_right"/>
    <child link="wheel_back_right_link"/>
    <axis xyz="0.0 0.0 1.0"/>
  </joint>
  <link name="wheel_forward_right_link">
    <inertial>
      <origin rpy="0.0 0.0 0.0" xyz="0.0 0.0 0.0"/>
      <mass value="2.7"/>
      <inertia ixx="1.086912" ixy="0.0" ixz="0.0" iyy="1.086912" iyz="0.0" izz="1.086912"/>
    </inertial>
    <visual name="wheel_l">
      <geometry>
        <cylinder length="0.04" radius="0.08"/>
      </geometry>
      <material name="black">
        <color rgba="0.27 0.27 0.27 1"/>
      </material>
    </visual>
    <collision>
      <geometry>
        <sphere radius="0.08"/>
        <!-- length="0.04" -->
      </geometry>
      <material name="black">
        <color rgba="0.27 0.27 0.27 1"/>
      </material>
    </collision>
  </link>
  <joint name="wheel_forward_right_joint" type="continuous">
    <origin rpy="-1.57 0 0" xyz="0.785 -0.43 0.08"/>
    <parent link="base_link"/>
    <child link="wheel_forward_right_link"/>
    <axis xyz="0.0 0.0 1.0"/>
  </joint>
  <gazebo reference="wheel_forward_right_link">
    <mu1 value="0.0001"/>
    <mu2 value="0.0001"/>
  </gazebo>
  <link name="wheel_back_left_link">
    <inertial>
      <origin rpy="0.0 0.0 0.0" xyz="0.0 0.0 0.0"/>
      <mass value="2.7"/>
      <inertia ixx="1.086912" ixy="0.0" ixz="0.0" iyy="1.086912" iyz="0.0" izz="1.086912"/>
    </inertial>
    <visual name="wheel_l">
      <geometry>
        <cylinder length="0.04" radius="0.08"/>
      </geometry>
      <material name="black">
        <color rgba="0.27 0.27 0.27 1"/>
      </material>
    </visual>
    <collision>
      <geometry>
        <sphere radius="0.08"/>
        <!-- length="0.04" -->
      </geometry>
      <material name="black">
        <color rgba="0.27 0.27 0.27 1"/>
      </material>
    </collision>
  </link>
  <joint name="wheel_back_left_joint" type="continuous">
    <origin rpy="-1.57 0 0" xyz="-0.785 0.43 0.08"/>
    <parent link="base_link"/>
    <child link="wheel_back_left_link"/>
    <axis xyz="0.0 0.0 1.0"/>
  </joint>
  <gazebo reference="wheel_back_left_link">
    <mu1 value="0.0001"/>
    <mu2 value="0.0001"/>
  </gazebo>
  <!-- WHEEL END -->
</robot>
