<?xml version="1.0" ?>
<robot name="potrol"  xmlns:xacro="http://www.ros.org/wiki/xacro">

    <material name="Blue">
        <color rgba="0.03 0.01 0.97 1"/>
    </material>
    <material name="Yellow">
        <color rgba="0.82 0.8 0.08 1"/>
    </material>
    <material name="Black">
        <color rgba="0.27 0.27 0.27 1"/>
    </material>
    <material name="gray2">
        <color rgba="0.76 0.76 0.76 1"/>
    </material>
    <material name="gray">
        <color rgba="0.76 0.76 0.76 1"/>
    </material>


    <link name="base_footprint"> 
    </link>
    <!-- BASE LINK -->

    <link name="base_link">
        <inertial>
            <origin xyz="0.0 0.0 0.58" rpy="0.0 0.0 1.57"/>
            <mass value="10.0"/>
            <inertia  ixx="0.544083333333" ixy="0" ixz="0" iyy="0.544083333333" iyz="0" izz="0.384" />        
        </inertial>
        <visual>
            <origin rpy="0 0 1.57" xyz="0 0 0"/>
            <geometry>
                <!-- <box size="0.48 0.48 0.650"/> -->
                <mesh filename="package://potrol_description_cmake/meshes/robo_frame.stl" scale="0.75 0.75 0.75"/>
            </geometry>
            <material name="gray"/>

        </visual>
        <collision>
            <origin rpy="0 0 1.57" xyz="0 0 0"/>
            <geometry>
                <!-- <box size="0.48 0.48 0.650"/> -->

                <mesh filename="package://potrol_description_cmake/meshes/robo_frame.stl" scale="0.75 0.75 0.75"/>

            </geometry>
            
        </collision>
    </link>

    <joint name="base_joint" type="fixed">
        <origin xyz="0.0 0.0 0.03" rpy="0.0 0.0 0"/>
        <!-- <origin xyz="0.0 0.0 0.42" rpy="0.0 0.0 1.57"/> -->
        <parent link="base_footprint" />
        <child link="base_link" />
        <axis xyz="0.0 0.0 0"/>
    </joint>
    <!-- BASE LINK END -->

    <!-- CAMERA -->

    <joint name="camera_joint" type="fixed">
        <parent link="base_link"/>
        <child link="camera_link"/>
        <origin xyz="0.249564 -0.0 0.227776" rpy="0 0 0"/>
    </joint>

    <!-- CAMERA END -->
   
    <!-- LiDAR -->
    <joint name="laser_joint" type="fixed">
        <parent link="base_link"/>
        <child link="laser_frame"/>
        <origin xyz="0.156491 0.0 0.813175" rpy="0 0 0"/>
    </joint>

    <link name="laser_frame">
        <visual>
            <geometry>
                <cylinder radius="0.0375" length="0.04"/>
            </geometry>
            <material name="Black"/>
        </visual>
        <collision>
            <geometry>
                <cylinder radius="0.0375" length="0.03"/>
            </geometry>
        </collision>
        <inertial>
            <origin xyz="0.0 0.0 0.0" rpy="0.0 0.0 0.0"/>
            <mass value="0.1"/>
            <inertia  ixx="1.01633333333" ixy="0" ixz="0" iyy="1.01633333333" iyz="0" izz="0.682666666667" />
        </inertial>
    </link>
    <!-- LiDAR END -->
   

    <!-- WHEEL -->

    <xacro:macro name="big_wheel" params="name x y z p">
        <link name="wheel_${name}_link">
           <inertial>
                <origin xyz="0.0 0.0 0.0" rpy="0.0 0.0 0.0"/>
                <mass value="4.1"/>
                <inertia  ixx="0.00631229166667" ixy="0" ixz="0" iyy="0.00631229166667" iyz="0" izz="0.01153125" />            
           </inertial>
            <visual>
                <geometry>
                    <cylinder radius="0.075" length="0.04"/>
                </geometry>
                <material name="Black"/>
                    
            </visual>

            <collision>
                <geometry>
                    <cylinder radius="0.075" length="0.038"/>
                </geometry>
            </collision>
        </link>

        <gazebo reference="wheel_${name}_link">
          <material>Gazebo/Gray</material>
          <mu1>1000000000000.0</mu1>
          <mu2>1000000000000.0</mu2>
          <!-- <kp>10000000000.0</kp>
          <kp>10.0</kp> -->
          <!-- <minDepth>0.001</minDepth> -->
        </gazebo>
        
        <joint name="wheel_${name}_joint" type="continuous">
            <origin rpy="-1.57 ${p} 0" xyz="${x} ${y} ${z}"/>
            <parent  link="base_footprint" />
            <child link="wheel_${name}_link"/>
            <axis xyz="0.0 0.0 1.0"/>
        </joint>

        <!-- <transmission name="wheel_${name}_transmission">
            <type>transmission_interface/SimpleTransmission</type>
            <joint name="wheel_${name}_joint">
              <hardwareInterface>hardware_interface/VelocityJointInterface</hardwareInterface>
            </joint>
            <actuator name="wheel_${name}_motor">
              <hardwareInterface>VelocityJointInterface</hardwareInterface>
              <mechanicalReduction>1</mechanicalReduction>
            </actuator>
        </transmission>
        <gazebo reference="wheel_${name}_link">
          <material>Gazebo/Gray</material>
          <mu1>1000000000000.0</mu1>
          <mu2>1000000000000.0</mu2> -->
          <!-- <kp>10000000000.0</kp>
          <kp>10.0</kp> -->
          <!-- <minDepth>0.001</minDepth> -->

        <!-- </gazebo> -->
    </xacro:macro>

    <xacro:big_wheel name="forward_left"  x="0.21375" y="0.26775" z="0.1" p="0" /> 
    <xacro:big_wheel name="forward_right"  x="0.21375" y="-0.26775" z="0.1" p="0" /> 
    <xacro:big_wheel name="back_right"  x="-0.21375" y="-0.26775" z="0.1" p="0" /> 
    <xacro:big_wheel name="back_left"  x="-0.21375" y="0.26775" z="0.1" p="0" /> 

</robot>