<?xml version="1.0" ?>
<robot name="potrol"  xmlns:xacro="http://www.ros.org/wiki/xacro">

    
    <!-- BASE LINK -->
    <link name="base_link">
        <inertial>
            <origin xyz="0.0 0.0 0.0" rpy="0.0 0.0 0.0"/>
            <mass value="30.0"/>
            <!-- <inertia  ixx="0.19210702797892856" ixy="0" ixz="0" iyy="0.284531244978989" iyz="0" izz="0.15909088366672705" />                -->
            <!-- <inertia  ixx="1440.8027098419643" ixy="0" ixz="0" iyy="2133.9843373424173" iyz="0" izz="1193.181627500453" /> -->
            <!-- <inertia  ixx="1.4408027098419643" ixy="0" ixz="0" iyy="2.1339843373424173" iyz="0" izz="1.193181627500453" /> -->
            <inertia  ixx="0.4036570743693346" ixy="0" ixz="0" iyy="0.8343288512691416" iyz="0" izz="1.1286581468243995" />

        </inertial>
        <visual>
            <origin rpy="0 0 0" xyz="0 0 0"/>
            <geometry>
                <!-- <box size="0.48 0.48 0.650"/> -->
                <mesh filename="package://potrol_description_cmake/meshes/potrol_frame_v2.dae" scale="1 1 1"/>
                <!-- <mesh filename="$(find potrol_description)/meshes/potrol_frame_v2.dae" scale="1 1 1"/> -->
                
            </geometry>
            <material name="gray"/>

        </visual>
        <collision>
            <origin rpy="0 0 0" xyz="0 0 0"/>
            <geometry>
                <!-- <box size="0.48 0.48 0.650"/> -->
                
                <mesh filename="package://potrol_description_cmake/meshes/potrol_frame_v2.dae" scale="1 1 1"/>
                
                <!-- <mesh filename="$(find potrol_description)/meshes/potrol_frame_v2.dae" scale="1 1 1"/> -->

                
            </geometry>
            
        </collision>
    </link>   

   

    <!-- BASE LINK END -->

    <!-- WHEEL_FRAME -->

    <xacro:macro name="connnect_frame" params="name x y z p yy">
        <link name="wheel_connnect_frame_${name}_link">
           <inertial>
                <origin xyz="0.0 0.0 0.0" rpy="0.0 0.0 0.0"/>
                <mass value="1"/>
                <!-- <inertia  ixx="0.0631229166667" ixy="0" ixz="0" iyy="0.0631229166667" iyz="0" izz="0.1153125" />                        -->
                <!-- <inertia  ixx="0.631229166667" ixy="0" ixz="0" iyy="0.631229166667" iyz="0" izz="1.153125" />                        -->
                <!-- <inertia  ixx="473.66666666666663" ixy="0" ixz="0" iyy="499.0685634265343" iyz="0" izz="156.06856342653433" /> -->
                <inertia  ixx="0.014209999964535239" ixy="0" ixz="0" iyy="0.014972055069813195" iyz="0" izz="0.004682054825732177" />

           </inertial>
            <visual>
                <geometry>
                    <!-- <cylinder radius="0.075" length="0.04"/> -->
                    <mesh filename="package://potrol_description_cmake/meshes/connnect_frame.dae" scale="1 1 1"/>
                    <!-- <mesh filename="$(find potrol_description)/meshes/connnect_frame.dae" scale="1 1 1"/> -->

                </geometry>
                <material name="Black"/>
                    
            </visual>

            <collision>
                <geometry>
                    <!-- <cylinder radius="0.075" length="0.038"/> -->
                    <mesh filename="package://potrol_description_cmake/meshes/connnect_frame.dae" scale="1 1 1"/>
                    <!-- <mesh filename="$(find potrol_description)/meshes/connnect_frame.dae" scale="1 1 1"/> -->

                </geometry>
            </collision>
        </link>
        
        <!-- <joint name="wheel_connnect_frame_${name}_joint" type="fixed"> -->
        <joint name="wheel_connnect_frame_${name}_joint" type="continuous">
            <origin rpy="0 ${p} ${yy}" xyz="${x} ${y} ${z}"/>
            <parent  link="base_link" />
            <child link="wheel_connnect_frame_${name}_link"/>
            <axis xyz="0.0 0.0 1.0"/>
        </joint>

        
        <gazebo reference="wheel_${name}_link">
          <material>Gazebo/Gray</material>
        </gazebo>
    </xacro:macro>

    

    <xacro:connnect_frame name="forward_left"  x="0.307287" y="0.170165" z="0.032513" p="0" yy="3.14" /> 
    <xacro:connnect_frame name="forward_right"  x="0.307287" y="-0.170165" z="0.032513" p="0" yy="0" /> 
    
    <!-- WHEEL_FRAME_END -->
    

    <!-- WHEEL -->
    <!-- forward -->
    <xacro:macro name="big_wheel_forward" params="name x y z p yy">
        <link name="wheel_${name}_link">
           <inertial>
                <origin xyz="0.0 0.0 0.0" rpy="0.0 0.0 0.0"/>
                <mass value="4.1"/>
                <!-- <inertia  ixx="0.12470068982515366" ixy="0" ixz="0" iyy="0.19017291756507977" iyz="0" izz="0.12457372773992613" /> -->
                <!-- <inertia  ixx="12470.068982515366" ixy="0" ixz="0" iyy="19017.291756507977" iyz="0" izz="12457.372773992613" /> -->
                <!-- <inertia  ixx="1.2470068982515366" ixy="0" ixz="0" iyy="1.9017291756507977" iyz="0" izz="1.2457372773992613" /> -->
                <inertia  ixx="0.0912444080325564" ixy="0" ixz="0" iyy="0.1391509116158557" iyz="0" izz="0.0911514987052553" />

            
           </inertial>
            <visual>
                <geometry>
                    <!-- <cylinder radius="0.075" length="0.04"/> -->
                    <mesh filename="package://potrol_description_cmake/meshes/wheel.dae" scale="1 1 1"/>
                    <!-- <mesh filename="$(find potrol_description)/meshes/wheel.dae" scale="1 1 1"/> -->

                </geometry>
                <material name="Black"/>
                    
            </visual>

            <collision>
                <geometry>
                    <!-- <cylinder radius="0.075" length="0.038"/> -->
                    <mesh filename="package://potrol_description_cmake/meshes/wheel.dae" scale="1 1 1"/>
                    <!-- <mesh filename="$(find potrol_description)/meshes/wheel.dae" scale="1 1 1"/> -->

                </geometry>
            </collision>
        </link>
        
        <joint name="wheel_${name}_joint" type="continuous">
            <origin rpy="0 ${p} ${yy}" xyz="${x} ${y} ${z}"/>
            <parent  link="wheel_connnect_frame_${name}_link" />
            <child link="wheel_${name}_link"/>
            <axis xyz="0.0 1.0 0.0"/>
        </joint>
        
        <gazebo reference="wheel_${name}_link">
          <material>Gazebo/Gray</material>
          <mu>1.0</mu>
          <mu2>1.0</mu2>
        </gazebo>
    </xacro:macro>

    <xacro:big_wheel_forward name="forward_left"  x="0.0" y="-0.05" z="0.0" p="0" yy="3.14" /> 
    <xacro:big_wheel_forward name="forward_right"  x="0.0" y="-0.05" z="0.0" p="0" yy="0.0"/> 
    <!-- <xacro:big_wheel name="back_right"  x="-0.21375" y="-0.26775" z="0.08" p="0" /> 
    <xacro:big_wheel name="back_left"  x="-0.21375" y="0.26775" z="0.08" p="0" />  -->

    <!-- backward -->
    <xacro:macro name="big_wheel_backward" params="name x y z p">
        <link name="wheel_${name}_link">
           <inertial>
                <origin xyz="0.0 0.0 0.0" rpy="0.0 0.0 0.0"/>
                <mass value="4.1"/>
                <!-- <inertia  ixx="0.12470068982515366" ixy="0" ixz="0" iyy="0.19017291756507977" iyz="0" izz="0.12457372773992613" /> -->
                <!-- <inertia  ixx="1.2470068982515366" ixy="0" ixz="0" iyy="1.9017291756507977" iyz="0" izz="1.2457372773992613" /> -->
                <inertia  ixx="0.0912444080325564" ixy="0" ixz="0" iyy="0.1391509116158557" iyz="0" izz="0.0911514987052553" />
           </inertial>
            <visual>
                <geometry>
                    <!-- <cylinder radius="0.075" length="0.04"/> -->
                    <mesh filename="package://potrol_description_cmake/meshes/wheel.dae" scale="1 1 1"/>
                    <!-- <mesh filename="$(find potrol_description)/meshes/wheel.dae" scale="1 1 1"/> -->
                </geometry>
                <material name="Black"/>
                    
            </visual>

            <collision>
                <geometry>
                    <!-- <cylinder radius="0.075" length="0.038"/> -->
                    <mesh filename="package://potrol_description_cmake/meshes/wheel.dae" scale="1 1 1"/>
                    <!-- <mesh filename="$(find potrol_description)/meshes/wheel.dae" scale="1 1 1"/> -->
                    <!-- <cylinder radius="0.075" length="0.04"/> -->

                </geometry>
            </collision>
        </link>
        
        <joint name="wheel_${name}_joint" type="continuous">
            <origin rpy="0 ${p} 0" xyz="${x} ${y} ${z}"/>
            <parent  link="base_link" />
            <child link="wheel_${name}_link"/>
            <axis xyz="1.0 0.0 0.0"/>
        </joint>

        
        <gazebo reference="wheel_${name}_link">
          <material>Gazebo/Gray</material>
          <mu>1.0</mu>
          <mu2>1.0</mu2>
        </gazebo>
    </xacro:macro>

    <xacro:big_wheel_backward name="backward_left"  x="-0.165050" y="0.220515" z="0.029786" p="0" /> 
    <xacro:big_wheel_backward name="backward_right"  x="-0.165050" y="-0.220515" z="0.029786" p="0" />

    <!-- WHEEL_END-->

    <!-- CAMERA -->
    <joint name="camera_joint" type="fixed">
        <parent link="base_link"/>
        <child link="camera_link"/>
        <origin xyz="0.37 -0.004 0.035" rpy="0 0 0"/>
    </joint>

    <!-- CAMERA END -->

</robot>
